{
  "configurations": {
    "CVE_data_version": "4.0",
    "nodes": []
  },
  "cve": {
    "CVE_data_meta": {
      "ASSIGNER": "cve@mitre.org",
      "ID": "CVE-2022-48560"
    },
    "data_format": "MITRE",
    "data_type": "CVE",
    "data_version": "4.0",
    "description": {
      "description_data": [
        {
          "lang": "en",
          "value": "A use-after-free exists in Python through 3.9 via heappushpop in heapq."
        }
      ]
    },
    "problemtype": {
      "problemtype_data": [
        {
          "description": []
        }
      ]
    },
    "references": {
      "reference_data": [
        {
          "name": "https://bugs.python.org/issue39421",
          "refsource": "MISC",
          "tags": [],
          "url": "https://bugs.python.org/issue39421"
        }
      ]
    }
  },
  "impact": {},
  "lastModifiedDate": "2023-08-22T20:10Z",
  "publishedDate": "2023-08-22T19:16Z"
}