{
  "Identifier": "CVE-2023-28859",
  "PackageSlug": "pypi/redis",
  "Title": "redis-py Race Condition due to incomplete fix",
  "Description": "redis-py through 4.5.3 leaves a connection open after canceling an async Redis command at an inopportune time (in the case of a non-pipeline operation), and can send response data to the client of an unrelated request. NOTE: this issue exists because of an incomplete fix for CVE-2023-28858.",
  "Date": "2023-04-05",
  "Pubdate": "2023-03-26",
  "AffectedRange": "\u003c=4.5.3",
  "FixedVersions": [
    "4.5.4"
  ],
  "AffectedVersions": "All versions up to 4.5.3",
  "NotImpacted": "All versions after 4.5.3",
  "Solution": "Upgrade to version 4.5.4 or above.",
  "Urls": [
    "https://nvd.nist.gov/vuln/detail/CVE-2023-28859",
    "https://github.com/redis/redis-py/issues/2665",
    "https://github.com/redis/redis-py/pull/2641",
    "https://github.com/advisories/GHSA-8fww-64cx-x8p5"
  ],
  "CvssV2": "",
  "CvssV3": "CVSS:3.1/AV:N/AC:L/PR:L/UI:N/S:U/C:H/I:N/A:N",
  "UUID": "807ee8a6-3fd2-4e47-a65e-ae0f0e1e89bd"
}