{
  "configurations": {
    "CVE_data_version": "4.0",
    "nodes": []
  },
  "cve": {
    "CVE_data_meta": {
      "ASSIGNER": "cve@mitre.org",
      "ID": "CVE-2023-29824"
    },
    "data_format": "MITRE",
    "data_type": "CVE",
    "data_version": "4.0",
    "description": {
      "description_data": [
        {
          "lang": "en",
          "value": "** DISPUTED ** A use-after-free issue was discovered in Py_FindObjects() function in SciPy versions prior to 1.8.0. NOTE: the vendor and discoverer indicate that this is not a security issue."
        }
      ]
    },
    "problemtype": {
      "problemtype_data": [
        {
          "description": []
        }
      ]
    },
    "references": {
      "reference_data": [
        {
          "name": "https://github.com/scipy/scipy/issues/14713",
          "refsource": "MISC",
          "tags": [],
          "url": "https://github.com/scipy/scipy/issues/14713"
        },
        {
          "name": "http://www.square16.org/achievement/cve-2023-29824/",
          "refsource": "MISC",
          "tags": [],
          "url": "http://www.square16.org/achievement/cve-2023-29824/"
        },
        {
          "name": "https://github.com/scipy/scipy/pull/15013",
          "refsource": "MISC",
          "tags": [],
          "url": "https://github.com/scipy/scipy/pull/15013"
        },
        {
          "name": "https://github.com/scipy/scipy/issues/14713#issuecomment-1629468565",
          "refsource": "MISC",
          "tags": [],
          "url": "https://github.com/scipy/scipy/issues/14713#issuecomment-1629468565"
        }
      ]
    }
  },
  "impact": {},
  "lastModifiedDate": "2023-07-11T18:15Z",
  "publishedDate": "2023-07-06T21:15Z"
}