{
  "configurations": {
    "CVE_data_version": "4.0",
    "nodes": []
  },
  "cve": {
    "CVE_data_meta": {
      "ASSIGNER": "cve@mitre.org",
      "ID": "CVE-2023-39661"
    },
    "data_format": "MITRE",
    "data_type": "CVE",
    "data_version": "4.0",
    "description": {
      "description_data": [
        {
          "lang": "en",
          "value": "An issue in pandas-ai v.0.9.1 and before allows a remote attacker to execute arbitrary code via the _is_jailbreak function."
        }
      ]
    },
    "problemtype": {
      "problemtype_data": [
        {
          "description": []
        }
      ]
    },
    "references": {
      "reference_data": [
        {
          "name": "https://github.com/gventuri/pandas-ai/issues/410",
          "refsource": "MISC",
          "tags": [],
          "url": "https://github.com/gventuri/pandas-ai/issues/410"
        }
      ]
    }
  },
  "impact": {},
  "lastModifiedDate": "2023-08-15T17:15Z",
  "publishedDate": "2023-08-15T17:15Z"
}